<?xml version="1.0"?>
<robot xmlns:xacro="http://ros.org/wiki/xacro">

  <xacro:include filename="$(find robot_description)/urdf/front_wheel/front_wheel.gazebo.xacro"/>
  
  <xacro:macro name="front_wheel_v0" params="prefix parent *joint_origin *joint_axis">
	<joint name="${prefix}_wheel_joint" type="continuous"> <!--continuous-->
	  <xacro:insert_block name="joint_origin"/>
	  <parent link="${parent}"/>
	  <child link="${prefix}_wheel_link"/>
         <limit effort="1.5" velocity="20"/>
	  <xacro:insert_block name="joint_axis"/>
	</joint>

	<link name="${prefix}_wheel_link">
	  <visual>
		<geometry>
		  <mesh filename="package://robot_description/meshes/DAE/front_wheel/wheel.dae"/>
		</geometry>
	  </visual>
	  <collision>
		<geometry>
		  <mesh filename="package://robot_description/meshes/STL/front_wheel/wheel.stl"/>
		</geometry>
	  </collision>
	  <inertial>
		<origin xyz="0 0 0"/>
		<mass value="0.137"/>
		<inertia ixx="0.00006" ixy="0" ixz="0" iyy="0.00011" iyz="0" izz="0.00006"/>
	  </inertial>
	</link>
  </xacro:macro>
  
</robot>

